[2024-12-23 14:10:27,432] INFO in app: Initialisation WandB rÃ©ussie pour le projet IFT6758.2024-A04 et l'entitÃ© thalia-cantero-udem.
--- Logging error ---
Traceback (most recent call last):
  File "C:\Users\Cloud\anaconda3\envs\ift2125\Lib\logging\handlers.py", line 74, in emit
    self.doRollover()
  File "C:\Users\Cloud\anaconda3\envs\ift2125\Lib\logging\handlers.py", line 179, in doRollover
    self.rotate(self.baseFilename, dfn)
  File "C:\Users\Cloud\anaconda3\envs\ift2125\Lib\logging\handlers.py", line 115, in rotate
    os.rename(source, dest)
PermissionError: [WinError 32] Le processus ne peut pas accÃ©der au fichier car ce fichier est utilisÃ© par un autre processus: "C:\\Users\\Cloud\\OneDrive\\Bureau\\UdeM\\Session d'automne\\data Science\\projet3\\python\\milestone3\\docker-project (1)\\docker-project\\serving\\flask.log" -> "C:\\Users\\Cloud\\OneDrive\\Bureau\\UdeM\\Session d'automne\\data Science\\projet3\\python\\milestone3\\docker-project (1)\\docker-project\\serving\\flask.log.1"
Call stack:
  File "C:\Users\Cloud\anaconda3\envs\ift2125\Lib\threading.py", line 1009, in _bootstrap
    self._bootstrap_inner()
  File "C:\Users\Cloud\anaconda3\envs\ift2125\Lib\threading.py", line 1052, in _bootstrap_inner
    self.run()
  File "C:\Users\Cloud\anaconda3\envs\ift2125\Lib\threading.py", line 989, in run
    self._target(*self._args, **self._kwargs)
  File "C:\Users\Cloud\anaconda3\envs\ift2125\Lib\site-packages\waitress\task.py", line 83, in handler_thread
    task.service()
  File "C:\Users\Cloud\anaconda3\envs\ift2125\Lib\site-packages\waitress\channel.py", line 430, in service
    task.service()
  File "C:\Users\Cloud\anaconda3\envs\ift2125\Lib\site-packages\waitress\task.py", line 167, in service
    self.execute()
  File "C:\Users\Cloud\anaconda3\envs\ift2125\Lib\site-packages\waitress\task.py", line 435, in execute
    app_iter = self.channel.server.application(environ, start_response)
  File "C:\Users\Cloud\anaconda3\envs\ift2125\Lib\site-packages\waitress\proxy_headers.py", line 64, in translate_proxy_headers
    return app(environ, start_response)
  File "C:\Users\Cloud\anaconda3\envs\ift2125\Lib\site-packages\flask\app.py", line 1536, in __call__
    return self.wsgi_app(environ, start_response)
  File "C:\Users\Cloud\anaconda3\envs\ift2125\Lib\site-packages\flask\app.py", line 1511, in wsgi_app
    response = self.full_dispatch_request()
  File "C:\Users\Cloud\anaconda3\envs\ift2125\Lib\site-packages\flask\app.py", line 917, in full_dispatch_request
    rv = self.dispatch_request()
  File "C:\Users\Cloud\anaconda3\envs\ift2125\Lib\site-packages\flask\app.py", line 902, in dispatch_request
    return self.ensure_sync(self.view_functions[rule.endpoint])(**view_args)  # type: ignore[no-any-return]
  File "C:\Users\Cloud\OneDrive\Bureau\UdeM\Session d'automne\data Science\projet3\python\milestone3\docker-project (1)\docker-project\serving\app.py", line 149, in download_registry_model
    app.logger.info(f"Initialisation WandB rÃ©ussie pour le projet {project} et l'entitÃ© {entity}.")
Message: "Initialisation WandB rÃ©ussie pour le projet IFT6758.2024-A04 et l'entitÃ© thalia-cantero-udem."
Arguments: ()
[2024-12-23 14:10:27,496] INFO in app: Downloading model artifact from: thalia-cantero-udem/IFT6758.2024-A04/expected-goal-distance:v1
--- Logging error ---
Traceback (most recent call last):
  File "C:\Users\Cloud\anaconda3\envs\ift2125\Lib\logging\handlers.py", line 74, in emit
    self.doRollover()
  File "C:\Users\Cloud\anaconda3\envs\ift2125\Lib\logging\handlers.py", line 179, in doRollover
    self.rotate(self.baseFilename, dfn)
  File "C:\Users\Cloud\anaconda3\envs\ift2125\Lib\logging\handlers.py", line 115, in rotate
    os.rename(source, dest)
PermissionError: [WinError 32] Le processus ne peut pas accÃ©der au fichier car ce fichier est utilisÃ© par un autre processus: "C:\\Users\\Cloud\\OneDrive\\Bureau\\UdeM\\Session d'automne\\data Science\\projet3\\python\\milestone3\\docker-project (1)\\docker-project\\serving\\flask.log" -> "C:\\Users\\Cloud\\OneDrive\\Bureau\\UdeM\\Session d'automne\\data Science\\projet3\\python\\milestone3\\docker-project (1)\\docker-project\\serving\\flask.log.1"
Call stack:
  File "C:\Users\Cloud\anaconda3\envs\ift2125\Lib\threading.py", line 1009, in _bootstrap
    self._bootstrap_inner()
  File "C:\Users\Cloud\anaconda3\envs\ift2125\Lib\threading.py", line 1052, in _bootstrap_inner
    self.run()
  File "C:\Users\Cloud\anaconda3\envs\ift2125\Lib\threading.py", line 989, in run
    self._target(*self._args, **self._kwargs)
  File "C:\Users\Cloud\anaconda3\envs\ift2125\Lib\site-packages\waitress\task.py", line 83, in handler_thread
    task.service()
  File "C:\Users\Cloud\anaconda3\envs\ift2125\Lib\site-packages\waitress\channel.py", line 430, in service
    task.service()
  File "C:\Users\Cloud\anaconda3\envs\ift2125\Lib\site-packages\waitress\task.py", line 167, in service
    self.execute()
  File "C:\Users\Cloud\anaconda3\envs\ift2125\Lib\site-packages\waitress\task.py", line 435, in execute
    app_iter = self.channel.server.application(environ, start_response)
  File "C:\Users\Cloud\anaconda3\envs\ift2125\Lib\site-packages\waitress\proxy_headers.py", line 64, in translate_proxy_headers
    return app(environ, start_response)
  File "C:\Users\Cloud\anaconda3\envs\ift2125\Lib\site-packages\flask\app.py", line 1536, in __call__
    return self.wsgi_app(environ, start_response)
  File "C:\Users\Cloud\anaconda3\envs\ift2125\Lib\site-packages\flask\app.py", line 1511, in wsgi_app
    response = self.full_dispatch_request()
  File "C:\Users\Cloud\anaconda3\envs\ift2125\Lib\site-packages\flask\app.py", line 917, in full_dispatch_request
    rv = self.dispatch_request()
  File "C:\Users\Cloud\anaconda3\envs\ift2125\Lib\site-packages\flask\app.py", line 902, in dispatch_request
    return self.ensure_sync(self.view_functions[rule.endpoint])(**view_args)  # type: ignore[no-any-return]
  File "C:\Users\Cloud\OneDrive\Bureau\UdeM\Session d'automne\data Science\projet3\python\milestone3\docker-project (1)\docker-project\serving\app.py", line 153, in download_registry_model
    app.logger.info(f"Downloading model artifact from: {artifact_path}")
Message: 'Downloading model artifact from: thalia-cantero-udem/IFT6758.2024-A04/expected-goal-distance:v1'
Arguments: ()
[34m[1mwandb[0m:   1 of 1 files downloaded.
[2024-12-23 14:10:28,954] ERROR in app: Failed to download model: [Errno 2] No such file or directory: "C:\\Users\\Cloud\\OneDrive\\Bureau\\UdeM\\Session d'automne\\data Science\\projet3\\python\\milestone3\\docker-project (1)\\docker-project\\models\\expected-goal-distance.pkl"
--- Logging error ---
Traceback (most recent call last):
  File "C:\Users\Cloud\OneDrive\Bureau\UdeM\Session d'automne\data Science\projet3\python\milestone3\docker-project (1)\docker-project\serving\app.py", line 160, in download_registry_model
    loaded_model = joblib.load(model_file_path)
                   ^^^^^^^^^^^^^^^^^^^^^^^^^^^^
  File "C:\Users\Cloud\anaconda3\envs\ift2125\Lib\site-packages\joblib\numpy_pickle.py", line 650, in load
    with open(filename, 'rb') as f:
         ^^^^^^^^^^^^^^^^^^^^
FileNotFoundError: [Errno 2] No such file or directory: "C:\\Users\\Cloud\\OneDrive\\Bureau\\UdeM\\Session d'automne\\data Science\\projet3\\python\\milestone3\\docker-project (1)\\docker-project\\models\\expected-goal-distance.pkl"

During handling of the above exception, another exception occurred:

Traceback (most recent call last):
  File "C:\Users\Cloud\anaconda3\envs\ift2125\Lib\logging\handlers.py", line 74, in emit
    self.doRollover()
  File "C:\Users\Cloud\anaconda3\envs\ift2125\Lib\logging\handlers.py", line 179, in doRollover
    self.rotate(self.baseFilename, dfn)
  File "C:\Users\Cloud\anaconda3\envs\ift2125\Lib\logging\handlers.py", line 115, in rotate
    os.rename(source, dest)
PermissionError: [WinError 32] Le processus ne peut pas accÃ©der au fichier car ce fichier est utilisÃ© par un autre processus: "C:\\Users\\Cloud\\OneDrive\\Bureau\\UdeM\\Session d'automne\\data Science\\projet3\\python\\milestone3\\docker-project (1)\\docker-project\\serving\\flask.log" -> "C:\\Users\\Cloud\\OneDrive\\Bureau\\UdeM\\Session d'automne\\data Science\\projet3\\python\\milestone3\\docker-project (1)\\docker-project\\serving\\flask.log.1"
Call stack:
  File "C:\Users\Cloud\anaconda3\envs\ift2125\Lib\threading.py", line 1009, in _bootstrap
    self._bootstrap_inner()
  File "C:\Users\Cloud\anaconda3\envs\ift2125\Lib\threading.py", line 1052, in _bootstrap_inner
    self.run()
  File "C:\Users\Cloud\anaconda3\envs\ift2125\Lib\threading.py", line 989, in run
    self._target(*self._args, **self._kwargs)
  File "C:\Users\Cloud\anaconda3\envs\ift2125\Lib\site-packages\waitress\task.py", line 83, in handler_thread
    task.service()
  File "C:\Users\Cloud\anaconda3\envs\ift2125\Lib\site-packages\waitress\channel.py", line 430, in service
    task.service()
  File "C:\Users\Cloud\anaconda3\envs\ift2125\Lib\site-packages\waitress\task.py", line 167, in service
    self.execute()
  File "C:\Users\Cloud\anaconda3\envs\ift2125\Lib\site-packages\waitress\task.py", line 435, in execute
    app_iter = self.channel.server.application(environ, start_response)
  File "C:\Users\Cloud\anaconda3\envs\ift2125\Lib\site-packages\waitress\proxy_headers.py", line 64, in translate_proxy_headers
    return app(environ, start_response)
  File "C:\Users\Cloud\anaconda3\envs\ift2125\Lib\site-packages\flask\app.py", line 1536, in __call__
    return self.wsgi_app(environ, start_response)
  File "C:\Users\Cloud\anaconda3\envs\ift2125\Lib\site-packages\flask\app.py", line 1511, in wsgi_app
    response = self.full_dispatch_request()
  File "C:\Users\Cloud\anaconda3\envs\ift2125\Lib\site-packages\flask\app.py", line 917, in full_dispatch_request
    rv = self.dispatch_request()
  File "C:\Users\Cloud\anaconda3\envs\ift2125\Lib\site-packages\flask\app.py", line 902, in dispatch_request
    return self.ensure_sync(self.view_functions[rule.endpoint])(**view_args)  # type: ignore[no-any-return]
  File "C:\Users\Cloud\OneDrive\Bureau\UdeM\Session d'automne\data Science\projet3\python\milestone3\docker-project (1)\docker-project\serving\app.py", line 165, in download_registry_model
    app.logger.error(f"Failed to download model: {e}")
Message: 'Failed to download model: [Errno 2] No such file or directory: "C:\\\\Users\\\\Cloud\\\\OneDrive\\\\Bureau\\\\UdeM\\\\Session d\'automne\\\\data Science\\\\projet3\\\\python\\\\milestone3\\\\docker-project (1)\\\\docker-project\\\\models\\\\expected-goal-distance.pkl"'
Arguments: ()
[2024-12-23 14:11:23,400] INFO in app: {'entity': 'thalia-cantero-udem', 'project': 'IFT6758.2024-A04', 'model': 'expected-goal-model-angle-and-distance', 'version': 'v2'}
--- Logging error ---
Traceback (most recent call last):
  File "C:\Users\Cloud\anaconda3\envs\ift2125\Lib\logging\handlers.py", line 74, in emit
    self.doRollover()
  File "C:\Users\Cloud\anaconda3\envs\ift2125\Lib\logging\handlers.py", line 179, in doRollover
    self.rotate(self.baseFilename, dfn)
  File "C:\Users\Cloud\anaconda3\envs\ift2125\Lib\logging\handlers.py", line 115, in rotate
    os.rename(source, dest)
PermissionError: [WinError 32] Le processus ne peut pas accÃ©der au fichier car ce fichier est utilisÃ© par un autre processus: "C:\\Users\\Cloud\\OneDrive\\Bureau\\UdeM\\Session d'automne\\data Science\\projet3\\python\\milestone3\\docker-project (1)\\docker-project\\serving\\flask.log" -> "C:\\Users\\Cloud\\OneDrive\\Bureau\\UdeM\\Session d'automne\\data Science\\projet3\\python\\milestone3\\docker-project (1)\\docker-project\\serving\\flask.log.1"
Call stack:
  File "C:\Users\Cloud\anaconda3\envs\ift2125\Lib\threading.py", line 1009, in _bootstrap
    self._bootstrap_inner()
  File "C:\Users\Cloud\anaconda3\envs\ift2125\Lib\threading.py", line 1052, in _bootstrap_inner
    self.run()
  File "C:\Users\Cloud\anaconda3\envs\ift2125\Lib\threading.py", line 989, in run
    self._target(*self._args, **self._kwargs)
  File "C:\Users\Cloud\anaconda3\envs\ift2125\Lib\site-packages\waitress\task.py", line 83, in handler_thread
    task.service()
  File "C:\Users\Cloud\anaconda3\envs\ift2125\Lib\site-packages\waitress\channel.py", line 430, in service
    task.service()
  File "C:\Users\Cloud\anaconda3\envs\ift2125\Lib\site-packages\waitress\task.py", line 167, in service
    self.execute()
  File "C:\Users\Cloud\anaconda3\envs\ift2125\Lib\site-packages\waitress\task.py", line 435, in execute
    app_iter = self.channel.server.application(environ, start_response)
  File "C:\Users\Cloud\anaconda3\envs\ift2125\Lib\site-packages\waitress\proxy_headers.py", line 64, in translate_proxy_headers
    return app(environ, start_response)
  File "C:\Users\Cloud\anaconda3\envs\ift2125\Lib\site-packages\flask\app.py", line 1536, in __call__
    return self.wsgi_app(environ, start_response)
  File "C:\Users\Cloud\anaconda3\envs\ift2125\Lib\site-packages\flask\app.py", line 1511, in wsgi_app
    response = self.full_dispatch_request()
  File "C:\Users\Cloud\anaconda3\envs\ift2125\Lib\site-packages\flask\app.py", line 917, in full_dispatch_request
    rv = self.dispatch_request()
  File "C:\Users\Cloud\anaconda3\envs\ift2125\Lib\site-packages\flask\app.py", line 902, in dispatch_request
    return self.ensure_sync(self.view_functions[rule.endpoint])(**view_args)  # type: ignore[no-any-return]
  File "C:\Users\Cloud\OneDrive\Bureau\UdeM\Session d'automne\data Science\projet3\python\milestone3\docker-project (1)\docker-project\serving\app.py", line 120, in download_registry_model
    app.logger.info(json)
Message: {'entity': 'thalia-cantero-udem', 'project': 'IFT6758.2024-A04', 'model': 'expected-goal-model-angle-and-distance', 'version': 'v2'}
Arguments: ()
[2024-12-23 14:11:23,519] INFO in app: Initialisation WandB rÃ©ussie pour le projet IFT6758.2024-A04 et l'entitÃ© thalia-cantero-udem.
--- Logging error ---
Traceback (most recent call last):
  File "C:\Users\Cloud\anaconda3\envs\ift2125\Lib\logging\handlers.py", line 74, in emit
    self.doRollover()
  File "C:\Users\Cloud\anaconda3\envs\ift2125\Lib\logging\handlers.py", line 179, in doRollover
    self.rotate(self.baseFilename, dfn)
  File "C:\Users\Cloud\anaconda3\envs\ift2125\Lib\logging\handlers.py", line 115, in rotate
    os.rename(source, dest)
PermissionError: [WinError 32] Le processus ne peut pas accÃ©der au fichier car ce fichier est utilisÃ© par un autre processus: "C:\\Users\\Cloud\\OneDrive\\Bureau\\UdeM\\Session d'automne\\data Science\\projet3\\python\\milestone3\\docker-project (1)\\docker-project\\serving\\flask.log" -> "C:\\Users\\Cloud\\OneDrive\\Bureau\\UdeM\\Session d'automne\\data Science\\projet3\\python\\milestone3\\docker-project (1)\\docker-project\\serving\\flask.log.1"
Call stack:
  File "C:\Users\Cloud\anaconda3\envs\ift2125\Lib\threading.py", line 1009, in _bootstrap
    self._bootstrap_inner()
  File "C:\Users\Cloud\anaconda3\envs\ift2125\Lib\threading.py", line 1052, in _bootstrap_inner
    self.run()
  File "C:\Users\Cloud\anaconda3\envs\ift2125\Lib\threading.py", line 989, in run
    self._target(*self._args, **self._kwargs)
  File "C:\Users\Cloud\anaconda3\envs\ift2125\Lib\site-packages\waitress\task.py", line 83, in handler_thread
    task.service()
  File "C:\Users\Cloud\anaconda3\envs\ift2125\Lib\site-packages\waitress\channel.py", line 430, in service
    task.service()
  File "C:\Users\Cloud\anaconda3\envs\ift2125\Lib\site-packages\waitress\task.py", line 167, in service
    self.execute()
  File "C:\Users\Cloud\anaconda3\envs\ift2125\Lib\site-packages\waitress\task.py", line 435, in execute
    app_iter = self.channel.server.application(environ, start_response)
  File "C:\Users\Cloud\anaconda3\envs\ift2125\Lib\site-packages\waitress\proxy_headers.py", line 64, in translate_proxy_headers
    return app(environ, start_response)
  File "C:\Users\Cloud\anaconda3\envs\ift2125\Lib\site-packages\flask\app.py", line 1536, in __call__
    return self.wsgi_app(environ, start_response)
  File "C:\Users\Cloud\anaconda3\envs\ift2125\Lib\site-packages\flask\app.py", line 1511, in wsgi_app
    response = self.full_dispatch_request()
  File "C:\Users\Cloud\anaconda3\envs\ift2125\Lib\site-packages\flask\app.py", line 917, in full_dispatch_request
    rv = self.dispatch_request()
  File "C:\Users\Cloud\anaconda3\envs\ift2125\Lib\site-packages\flask\app.py", line 902, in dispatch_request
    return self.ensure_sync(self.view_functions[rule.endpoint])(**view_args)  # type: ignore[no-any-return]
  File "C:\Users\Cloud\OneDrive\Bureau\UdeM\Session d'automne\data Science\projet3\python\milestone3\docker-project (1)\docker-project\serving\app.py", line 149, in download_registry_model
    app.logger.info(f"Initialisation WandB rÃ©ussie pour le projet {project} et l'entitÃ© {entity}.")
Message: "Initialisation WandB rÃ©ussie pour le projet IFT6758.2024-A04 et l'entitÃ© thalia-cantero-udem."
Arguments: ()
[2024-12-23 14:11:23,554] INFO in app: Downloading model artifact from: thalia-cantero-udem/IFT6758.2024-A04/expected-goal-model-angle-and-distance:v2
--- Logging error ---
Traceback (most recent call last):
  File "C:\Users\Cloud\anaconda3\envs\ift2125\Lib\logging\handlers.py", line 74, in emit
    self.doRollover()
  File "C:\Users\Cloud\anaconda3\envs\ift2125\Lib\logging\handlers.py", line 179, in doRollover
    self.rotate(self.baseFilename, dfn)
  File "C:\Users\Cloud\anaconda3\envs\ift2125\Lib\logging\handlers.py", line 115, in rotate
    os.rename(source, dest)
PermissionError: [WinError 32] Le processus ne peut pas accÃ©der au fichier car ce fichier est utilisÃ© par un autre processus: "C:\\Users\\Cloud\\OneDrive\\Bureau\\UdeM\\Session d'automne\\data Science\\projet3\\python\\milestone3\\docker-project (1)\\docker-project\\serving\\flask.log" -> "C:\\Users\\Cloud\\OneDrive\\Bureau\\UdeM\\Session d'automne\\data Science\\projet3\\python\\milestone3\\docker-project (1)\\docker-project\\serving\\flask.log.1"
Call stack:
  File "C:\Users\Cloud\anaconda3\envs\ift2125\Lib\threading.py", line 1009, in _bootstrap
    self._bootstrap_inner()
  File "C:\Users\Cloud\anaconda3\envs\ift2125\Lib\threading.py", line 1052, in _bootstrap_inner
    self.run()
  File "C:\Users\Cloud\anaconda3\envs\ift2125\Lib\threading.py", line 989, in run
    self._target(*self._args, **self._kwargs)
  File "C:\Users\Cloud\anaconda3\envs\ift2125\Lib\site-packages\waitress\task.py", line 83, in handler_thread
    task.service()
  File "C:\Users\Cloud\anaconda3\envs\ift2125\Lib\site-packages\waitress\channel.py", line 430, in service
    task.service()
  File "C:\Users\Cloud\anaconda3\envs\ift2125\Lib\site-packages\waitress\task.py", line 167, in service
    self.execute()
  File "C:\Users\Cloud\anaconda3\envs\ift2125\Lib\site-packages\waitress\task.py", line 435, in execute
    app_iter = self.channel.server.application(environ, start_response)
  File "C:\Users\Cloud\anaconda3\envs\ift2125\Lib\site-packages\waitress\proxy_headers.py", line 64, in translate_proxy_headers
    return app(environ, start_response)
  File "C:\Users\Cloud\anaconda3\envs\ift2125\Lib\site-packages\flask\app.py", line 1536, in __call__
    return self.wsgi_app(environ, start_response)
  File "C:\Users\Cloud\anaconda3\envs\ift2125\Lib\site-packages\flask\app.py", line 1511, in wsgi_app
    response = self.full_dispatch_request()
  File "C:\Users\Cloud\anaconda3\envs\ift2125\Lib\site-packages\flask\app.py", line 917, in full_dispatch_request
    rv = self.dispatch_request()
  File "C:\Users\Cloud\anaconda3\envs\ift2125\Lib\site-packages\flask\app.py", line 902, in dispatch_request
    return self.ensure_sync(self.view_functions[rule.endpoint])(**view_args)  # type: ignore[no-any-return]
  File "C:\Users\Cloud\OneDrive\Bureau\UdeM\Session d'automne\data Science\projet3\python\milestone3\docker-project (1)\docker-project\serving\app.py", line 153, in download_registry_model
    app.logger.info(f"Downloading model artifact from: {artifact_path}")
Message: 'Downloading model artifact from: thalia-cantero-udem/IFT6758.2024-A04/expected-goal-model-angle-and-distance:v2'
Arguments: ()
[2024-12-23 14:11:23,885] ERROR in app: Failed to download model: artifact 'expected-goal-model-angle-and-distance:v2' not found in 'thalia-cantero-udem/IFT6758.2024-A04'
--- Logging error ---
Traceback (most recent call last):
  File "C:\Users\Cloud\anaconda3\envs\ift2125\Lib\site-packages\wandb\apis\normalize.py", line 25, in wrapper
    return func(*args, **kwargs)
           ^^^^^^^^^^^^^^^^^^^^^
  File "C:\Users\Cloud\anaconda3\envs\ift2125\Lib\site-packages\wandb\apis\public\api.py", line 1210, in _artifact
    artifact = wandb.Artifact._from_name(
               ^^^^^^^^^^^^^^^^^^^^^^^^^^
  File "C:\Users\Cloud\anaconda3\envs\ift2125\Lib\site-packages\wandb\sdk\artifacts\artifact.py", line 279, in _from_name
    raise ValueError(f"artifact '{name}' not found in '{entity}/{project}'")
ValueError: artifact 'expected-goal-model-angle-and-distance:v2' not found in 'thalia-cantero-udem/IFT6758.2024-A04'

During handling of the above exception, another exception occurred:

Traceback (most recent call last):
  File "C:\Users\Cloud\OneDrive\Bureau\UdeM\Session d'automne\data Science\projet3\python\milestone3\docker-project (1)\docker-project\serving\app.py", line 154, in download_registry_model
    artifact = wandb.use_artifact(artifact_path, type="model")
               ^^^^^^^^^^^^^^^^^^^^^^^^^^^^^^^^^^^^^^^^^^^^^^^
  File "C:\Users\Cloud\anaconda3\envs\ift2125\Lib\site-packages\wandb\sdk\wandb_run.py", line 403, in wrapper_fn
    return func(self, *args, **kwargs)
           ^^^^^^^^^^^^^^^^^^^^^^^^^^^
  File "C:\Users\Cloud\anaconda3\envs\ift2125\Lib\site-packages\wandb\sdk\wandb_run.py", line 393, in wrapper
    return func(self, *args, **kwargs)
           ^^^^^^^^^^^^^^^^^^^^^^^^^^^
  File "C:\Users\Cloud\anaconda3\envs\ift2125\Lib\site-packages\wandb\sdk\wandb_run.py", line 3071, in use_artifact
    artifact = public_api._artifact(type=type, name=name)
               ^^^^^^^^^^^^^^^^^^^^^^^^^^^^^^^^^^^^^^^^^^
  File "C:\Users\Cloud\anaconda3\envs\ift2125\Lib\site-packages\wandb\apis\normalize.py", line 71, in wrapper
    raise CommError(message, err).with_traceback(sys.exc_info()[2])
  File "C:\Users\Cloud\anaconda3\envs\ift2125\Lib\site-packages\wandb\apis\normalize.py", line 25, in wrapper
    return func(*args, **kwargs)
           ^^^^^^^^^^^^^^^^^^^^^
  File "C:\Users\Cloud\anaconda3\envs\ift2125\Lib\site-packages\wandb\apis\public\api.py", line 1210, in _artifact
    artifact = wandb.Artifact._from_name(
               ^^^^^^^^^^^^^^^^^^^^^^^^^^
  File "C:\Users\Cloud\anaconda3\envs\ift2125\Lib\site-packages\wandb\sdk\artifacts\artifact.py", line 279, in _from_name
    raise ValueError(f"artifact '{name}' not found in '{entity}/{project}'")
wandb.errors.errors.CommError: artifact 'expected-goal-model-angle-and-distance:v2' not found in 'thalia-cantero-udem/IFT6758.2024-A04'

During handling of the above exception, another exception occurred:

Traceback (most recent call last):
  File "C:\Users\Cloud\anaconda3\envs\ift2125\Lib\logging\handlers.py", line 74, in emit
    self.doRollover()
  File "C:\Users\Cloud\anaconda3\envs\ift2125\Lib\logging\handlers.py", line 179, in doRollover
    self.rotate(self.baseFilename, dfn)
  File "C:\Users\Cloud\anaconda3\envs\ift2125\Lib\logging\handlers.py", line 115, in rotate
    os.rename(source, dest)
PermissionError: [WinError 32] Le processus ne peut pas accÃ©der au fichier car ce fichier est utilisÃ© par un autre processus: "C:\\Users\\Cloud\\OneDrive\\Bureau\\UdeM\\Session d'automne\\data Science\\projet3\\python\\milestone3\\docker-project (1)\\docker-project\\serving\\flask.log" -> "C:\\Users\\Cloud\\OneDrive\\Bureau\\UdeM\\Session d'automne\\data Science\\projet3\\python\\milestone3\\docker-project (1)\\docker-project\\serving\\flask.log.1"
Call stack:
  File "C:\Users\Cloud\anaconda3\envs\ift2125\Lib\threading.py", line 1009, in _bootstrap
    self._bootstrap_inner()
  File "C:\Users\Cloud\anaconda3\envs\ift2125\Lib\threading.py", line 1052, in _bootstrap_inner
    self.run()
  File "C:\Users\Cloud\anaconda3\envs\ift2125\Lib\threading.py", line 989, in run
    self._target(*self._args, **self._kwargs)
  File "C:\Users\Cloud\anaconda3\envs\ift2125\Lib\site-packages\waitress\task.py", line 83, in handler_thread
    task.service()
  File "C:\Users\Cloud\anaconda3\envs\ift2125\Lib\site-packages\waitress\channel.py", line 430, in service
    task.service()
  File "C:\Users\Cloud\anaconda3\envs\ift2125\Lib\site-packages\waitress\task.py", line 167, in service
    self.execute()
  File "C:\Users\Cloud\anaconda3\envs\ift2125\Lib\site-packages\waitress\task.py", line 435, in execute
    app_iter = self.channel.server.application(environ, start_response)
  File "C:\Users\Cloud\anaconda3\envs\ift2125\Lib\site-packages\waitress\proxy_headers.py", line 64, in translate_proxy_headers
    return app(environ, start_response)
  File "C:\Users\Cloud\anaconda3\envs\ift2125\Lib\site-packages\flask\app.py", line 1536, in __call__
    return self.wsgi_app(environ, start_response)
  File "C:\Users\Cloud\anaconda3\envs\ift2125\Lib\site-packages\flask\app.py", line 1511, in wsgi_app
    response = self.full_dispatch_request()
  File "C:\Users\Cloud\anaconda3\envs\ift2125\Lib\site-packages\flask\app.py", line 917, in full_dispatch_request
    rv = self.dispatch_request()
  File "C:\Users\Cloud\anaconda3\envs\ift2125\Lib\site-packages\flask\app.py", line 902, in dispatch_request
    return self.ensure_sync(self.view_functions[rule.endpoint])(**view_args)  # type: ignore[no-any-return]
  File "C:\Users\Cloud\OneDrive\Bureau\UdeM\Session d'automne\data Science\projet3\python\milestone3\docker-project (1)\docker-project\serving\app.py", line 165, in download_registry_model
    app.logger.error(f"Failed to download model: {e}")
Message: "Failed to download model: artifact 'expected-goal-model-angle-and-distance:v2' not found in 'thalia-cantero-udem/IFT6758.2024-A04'"
Arguments: ()
[2024-12-23 14:12:53,779] INFO in app: {'entity': 'thalia-cantero-udem', 'project': 'IFT6758.2024-A04', 'model': 'expected-goal-model-angle-and-distance', 'version': 'v1'}
--- Logging error ---
Traceback (most recent call last):
  File "C:\Users\Cloud\anaconda3\envs\ift2125\Lib\logging\handlers.py", line 74, in emit
    self.doRollover()
  File "C:\Users\Cloud\anaconda3\envs\ift2125\Lib\logging\handlers.py", line 179, in doRollover
    self.rotate(self.baseFilename, dfn)
  File "C:\Users\Cloud\anaconda3\envs\ift2125\Lib\logging\handlers.py", line 115, in rotate
    os.rename(source, dest)
PermissionError: [WinError 32] Le processus ne peut pas accÃ©der au fichier car ce fichier est utilisÃ© par un autre processus: "C:\\Users\\Cloud\\OneDrive\\Bureau\\UdeM\\Session d'automne\\data Science\\projet3\\python\\milestone3\\docker-project (1)\\docker-project\\serving\\flask.log" -> "C:\\Users\\Cloud\\OneDrive\\Bureau\\UdeM\\Session d'automne\\data Science\\projet3\\python\\milestone3\\docker-project (1)\\docker-project\\serving\\flask.log.1"
Call stack:
  File "C:\Users\Cloud\anaconda3\envs\ift2125\Lib\threading.py", line 1009, in _bootstrap
    self._bootstrap_inner()
  File "C:\Users\Cloud\anaconda3\envs\ift2125\Lib\threading.py", line 1052, in _bootstrap_inner
    self.run()
  File "C:\Users\Cloud\anaconda3\envs\ift2125\Lib\threading.py", line 989, in run
    self._target(*self._args, **self._kwargs)
  File "C:\Users\Cloud\anaconda3\envs\ift2125\Lib\site-packages\waitress\task.py", line 83, in handler_thread
    task.service()
  File "C:\Users\Cloud\anaconda3\envs\ift2125\Lib\site-packages\waitress\channel.py", line 430, in service
    task.service()
  File "C:\Users\Cloud\anaconda3\envs\ift2125\Lib\site-packages\waitress\task.py", line 167, in service
    self.execute()
  File "C:\Users\Cloud\anaconda3\envs\ift2125\Lib\site-packages\waitress\task.py", line 435, in execute
    app_iter = self.channel.server.application(environ, start_response)
  File "C:\Users\Cloud\anaconda3\envs\ift2125\Lib\site-packages\waitress\proxy_headers.py", line 64, in translate_proxy_headers
    return app(environ, start_response)
  File "C:\Users\Cloud\anaconda3\envs\ift2125\Lib\site-packages\flask\app.py", line 1536, in __call__
    return self.wsgi_app(environ, start_response)
  File "C:\Users\Cloud\anaconda3\envs\ift2125\Lib\site-packages\flask\app.py", line 1511, in wsgi_app
    response = self.full_dispatch_request()
  File "C:\Users\Cloud\anaconda3\envs\ift2125\Lib\site-packages\flask\app.py", line 917, in full_dispatch_request
    rv = self.dispatch_request()
  File "C:\Users\Cloud\anaconda3\envs\ift2125\Lib\site-packages\flask\app.py", line 902, in dispatch_request
    return self.ensure_sync(self.view_functions[rule.endpoint])(**view_args)  # type: ignore[no-any-return]
  File "C:\Users\Cloud\OneDrive\Bureau\UdeM\Session d'automne\data Science\projet3\python\milestone3\docker-project (1)\docker-project\serving\app.py", line 120, in download_registry_model
    app.logger.info(json)
Message: {'entity': 'thalia-cantero-udem', 'project': 'IFT6758.2024-A04', 'model': 'expected-goal-model-angle-and-distance', 'version': 'v1'}
Arguments: ()
[2024-12-23 14:12:53,866] INFO in app: Initialisation WandB rÃ©ussie pour le projet IFT6758.2024-A04 et l'entitÃ© thalia-cantero-udem.
--- Logging error ---
Traceback (most recent call last):
  File "C:\Users\Cloud\anaconda3\envs\ift2125\Lib\logging\handlers.py", line 74, in emit
    self.doRollover()
  File "C:\Users\Cloud\anaconda3\envs\ift2125\Lib\logging\handlers.py", line 179, in doRollover
    self.rotate(self.baseFilename, dfn)
  File "C:\Users\Cloud\anaconda3\envs\ift2125\Lib\logging\handlers.py", line 115, in rotate
    os.rename(source, dest)
PermissionError: [WinError 32] Le processus ne peut pas accÃ©der au fichier car ce fichier est utilisÃ© par un autre processus: "C:\\Users\\Cloud\\OneDrive\\Bureau\\UdeM\\Session d'automne\\data Science\\projet3\\python\\milestone3\\docker-project (1)\\docker-project\\serving\\flask.log" -> "C:\\Users\\Cloud\\OneDrive\\Bureau\\UdeM\\Session d'automne\\data Science\\projet3\\python\\milestone3\\docker-project (1)\\docker-project\\serving\\flask.log.1"
Call stack:
  File "C:\Users\Cloud\anaconda3\envs\ift2125\Lib\threading.py", line 1009, in _bootstrap
    self._bootstrap_inner()
  File "C:\Users\Cloud\anaconda3\envs\ift2125\Lib\threading.py", line 1052, in _bootstrap_inner
    self.run()
  File "C:\Users\Cloud\anaconda3\envs\ift2125\Lib\threading.py", line 989, in run
    self._target(*self._args, **self._kwargs)
  File "C:\Users\Cloud\anaconda3\envs\ift2125\Lib\site-packages\waitress\task.py", line 83, in handler_thread
    task.service()
  File "C:\Users\Cloud\anaconda3\envs\ift2125\Lib\site-packages\waitress\channel.py", line 430, in service
    task.service()
  File "C:\Users\Cloud\anaconda3\envs\ift2125\Lib\site-packages\waitress\task.py", line 167, in service
    self.execute()
  File "C:\Users\Cloud\anaconda3\envs\ift2125\Lib\site-packages\waitress\task.py", line 435, in execute
    app_iter = self.channel.server.application(environ, start_response)
  File "C:\Users\Cloud\anaconda3\envs\ift2125\Lib\site-packages\waitress\proxy_headers.py", line 64, in translate_proxy_headers
    return app(environ, start_response)
  File "C:\Users\Cloud\anaconda3\envs\ift2125\Lib\site-packages\flask\app.py", line 1536, in __call__
    return self.wsgi_app(environ, start_response)
  File "C:\Users\Cloud\anaconda3\envs\ift2125\Lib\site-packages\flask\app.py", line 1511, in wsgi_app
    response = self.full_dispatch_request()
  File "C:\Users\Cloud\anaconda3\envs\ift2125\Lib\site-packages\flask\app.py", line 917, in full_dispatch_request
    rv = self.dispatch_request()
  File "C:\Users\Cloud\anaconda3\envs\ift2125\Lib\site-packages\flask\app.py", line 902, in dispatch_request
    return self.ensure_sync(self.view_functions[rule.endpoint])(**view_args)  # type: ignore[no-any-return]
  File "C:\Users\Cloud\OneDrive\Bureau\UdeM\Session d'automne\data Science\projet3\python\milestone3\docker-project (1)\docker-project\serving\app.py", line 149, in download_registry_model
    app.logger.info(f"Initialisation WandB rÃ©ussie pour le projet {project} et l'entitÃ© {entity}.")
Message: "Initialisation WandB rÃ©ussie pour le projet IFT6758.2024-A04 et l'entitÃ© thalia-cantero-udem."
Arguments: ()
[2024-12-23 14:12:53,929] INFO in app: Downloading model artifact from: thalia-cantero-udem/IFT6758.2024-A04/expected-goal-model-angle-and-distance:v1
--- Logging error ---
Traceback (most recent call last):
  File "C:\Users\Cloud\anaconda3\envs\ift2125\Lib\logging\handlers.py", line 74, in emit
    self.doRollover()
  File "C:\Users\Cloud\anaconda3\envs\ift2125\Lib\logging\handlers.py", line 179, in doRollover
    self.rotate(self.baseFilename, dfn)
  File "C:\Users\Cloud\anaconda3\envs\ift2125\Lib\logging\handlers.py", line 115, in rotate
    os.rename(source, dest)
PermissionError: [WinError 32] Le processus ne peut pas accÃ©der au fichier car ce fichier est utilisÃ© par un autre processus: "C:\\Users\\Cloud\\OneDrive\\Bureau\\UdeM\\Session d'automne\\data Science\\projet3\\python\\milestone3\\docker-project (1)\\docker-project\\serving\\flask.log" -> "C:\\Users\\Cloud\\OneDrive\\Bureau\\UdeM\\Session d'automne\\data Science\\projet3\\python\\milestone3\\docker-project (1)\\docker-project\\serving\\flask.log.1"
Call stack:
  File "C:\Users\Cloud\anaconda3\envs\ift2125\Lib\threading.py", line 1009, in _bootstrap
    self._bootstrap_inner()
  File "C:\Users\Cloud\anaconda3\envs\ift2125\Lib\threading.py", line 1052, in _bootstrap_inner
    self.run()
  File "C:\Users\Cloud\anaconda3\envs\ift2125\Lib\threading.py", line 989, in run
    self._target(*self._args, **self._kwargs)
  File "C:\Users\Cloud\anaconda3\envs\ift2125\Lib\site-packages\waitress\task.py", line 83, in handler_thread
    task.service()
  File "C:\Users\Cloud\anaconda3\envs\ift2125\Lib\site-packages\waitress\channel.py", line 430, in service
    task.service()
  File "C:\Users\Cloud\anaconda3\envs\ift2125\Lib\site-packages\waitress\task.py", line 167, in service
    self.execute()
  File "C:\Users\Cloud\anaconda3\envs\ift2125\Lib\site-packages\waitress\task.py", line 435, in execute
    app_iter = self.channel.server.application(environ, start_response)
  File "C:\Users\Cloud\anaconda3\envs\ift2125\Lib\site-packages\waitress\proxy_headers.py", line 64, in translate_proxy_headers
    return app(environ, start_response)
  File "C:\Users\Cloud\anaconda3\envs\ift2125\Lib\site-packages\flask\app.py", line 1536, in __call__
    return self.wsgi_app(environ, start_response)
  File "C:\Users\Cloud\anaconda3\envs\ift2125\Lib\site-packages\flask\app.py", line 1511, in wsgi_app
    response = self.full_dispatch_request()
  File "C:\Users\Cloud\anaconda3\envs\ift2125\Lib\site-packages\flask\app.py", line 917, in full_dispatch_request
    rv = self.dispatch_request()
  File "C:\Users\Cloud\anaconda3\envs\ift2125\Lib\site-packages\flask\app.py", line 902, in dispatch_request
    return self.ensure_sync(self.view_functions[rule.endpoint])(**view_args)  # type: ignore[no-any-return]
  File "C:\Users\Cloud\OneDrive\Bureau\UdeM\Session d'automne\data Science\projet3\python\milestone3\docker-project (1)\docker-project\serving\app.py", line 153, in download_registry_model
    app.logger.info(f"Downloading model artifact from: {artifact_path}")
Message: 'Downloading model artifact from: thalia-cantero-udem/IFT6758.2024-A04/expected-goal-model-angle-and-distance:v1'
Arguments: ()
[34m[1mwandb[0m:   1 of 1 files downloaded.
[2024-12-23 14:12:55,000] ERROR in app: Failed to download model: [Errno 2] No such file or directory: "C:\\Users\\Cloud\\OneDrive\\Bureau\\UdeM\\Session d'automne\\data Science\\projet3\\python\\milestone3\\docker-project (1)\\docker-project\\models\\expected-goal-model-angle-and-distance.pkl"
--- Logging error ---
Traceback (most recent call last):
  File "C:\Users\Cloud\OneDrive\Bureau\UdeM\Session d'automne\data Science\projet3\python\milestone3\docker-project (1)\docker-project\serving\app.py", line 160, in download_registry_model
    loaded_model = joblib.load(model_file_path)
                   ^^^^^^^^^^^^^^^^^^^^^^^^^^^^
  File "C:\Users\Cloud\anaconda3\envs\ift2125\Lib\site-packages\joblib\numpy_pickle.py", line 650, in load
    with open(filename, 'rb') as f:
         ^^^^^^^^^^^^^^^^^^^^
FileNotFoundError: [Errno 2] No such file or directory: "C:\\Users\\Cloud\\OneDrive\\Bureau\\UdeM\\Session d'automne\\data Science\\projet3\\python\\milestone3\\docker-project (1)\\docker-project\\models\\expected-goal-model-angle-and-distance.pkl"

During handling of the above exception, another exception occurred:

Traceback (most recent call last):
  File "C:\Users\Cloud\anaconda3\envs\ift2125\Lib\logging\handlers.py", line 74, in emit
    self.doRollover()
  File "C:\Users\Cloud\anaconda3\envs\ift2125\Lib\logging\handlers.py", line 179, in doRollover
    self.rotate(self.baseFilename, dfn)
  File "C:\Users\Cloud\anaconda3\envs\ift2125\Lib\logging\handlers.py", line 115, in rotate
    os.rename(source, dest)
PermissionError: [WinError 32] Le processus ne peut pas accÃ©der au fichier car ce fichier est utilisÃ© par un autre processus: "C:\\Users\\Cloud\\OneDrive\\Bureau\\UdeM\\Session d'automne\\data Science\\projet3\\python\\milestone3\\docker-project (1)\\docker-project\\serving\\flask.log" -> "C:\\Users\\Cloud\\OneDrive\\Bureau\\UdeM\\Session d'automne\\data Science\\projet3\\python\\milestone3\\docker-project (1)\\docker-project\\serving\\flask.log.1"
Call stack:
  File "C:\Users\Cloud\anaconda3\envs\ift2125\Lib\threading.py", line 1009, in _bootstrap
    self._bootstrap_inner()
  File "C:\Users\Cloud\anaconda3\envs\ift2125\Lib\threading.py", line 1052, in _bootstrap_inner
    self.run()
  File "C:\Users\Cloud\anaconda3\envs\ift2125\Lib\threading.py", line 989, in run
    self._target(*self._args, **self._kwargs)
  File "C:\Users\Cloud\anaconda3\envs\ift2125\Lib\site-packages\waitress\task.py", line 83, in handler_thread
    task.service()
  File "C:\Users\Cloud\anaconda3\envs\ift2125\Lib\site-packages\waitress\channel.py", line 430, in service
    task.service()
  File "C:\Users\Cloud\anaconda3\envs\ift2125\Lib\site-packages\waitress\task.py", line 167, in service
    self.execute()
  File "C:\Users\Cloud\anaconda3\envs\ift2125\Lib\site-packages\waitress\task.py", line 435, in execute
    app_iter = self.channel.server.application(environ, start_response)
  File "C:\Users\Cloud\anaconda3\envs\ift2125\Lib\site-packages\waitress\proxy_headers.py", line 64, in translate_proxy_headers
    return app(environ, start_response)
  File "C:\Users\Cloud\anaconda3\envs\ift2125\Lib\site-packages\flask\app.py", line 1536, in __call__
    return self.wsgi_app(environ, start_response)
  File "C:\Users\Cloud\anaconda3\envs\ift2125\Lib\site-packages\flask\app.py", line 1511, in wsgi_app
    response = self.full_dispatch_request()
  File "C:\Users\Cloud\anaconda3\envs\ift2125\Lib\site-packages\flask\app.py", line 917, in full_dispatch_request
    rv = self.dispatch_request()
  File "C:\Users\Cloud\anaconda3\envs\ift2125\Lib\site-packages\flask\app.py", line 902, in dispatch_request
    return self.ensure_sync(self.view_functions[rule.endpoint])(**view_args)  # type: ignore[no-any-return]
  File "C:\Users\Cloud\OneDrive\Bureau\UdeM\Session d'automne\data Science\projet3\python\milestone3\docker-project (1)\docker-project\serving\app.py", line 165, in download_registry_model
    app.logger.error(f"Failed to download model: {e}")
Message: 'Failed to download model: [Errno 2] No such file or directory: "C:\\\\Users\\\\Cloud\\\\OneDrive\\\\Bureau\\\\UdeM\\\\Session d\'automne\\\\data Science\\\\projet3\\\\python\\\\milestone3\\\\docker-project (1)\\\\docker-project\\\\models\\\\expected-goal-model-angle-and-distance.pkl"'
Arguments: ()
[2024-12-23 14:13:32,384] INFO in app: {'entity': 'thalia-cantero-udem', 'project': 'IFT6758.2024-A04', 'model': 'expected-goal-distance', 'version': 'v2'}
--- Logging error ---
Traceback (most recent call last):
  File "C:\Users\Cloud\anaconda3\envs\ift2125\Lib\logging\handlers.py", line 74, in emit
    self.doRollover()
  File "C:\Users\Cloud\anaconda3\envs\ift2125\Lib\logging\handlers.py", line 179, in doRollover
    self.rotate(self.baseFilename, dfn)
  File "C:\Users\Cloud\anaconda3\envs\ift2125\Lib\logging\handlers.py", line 115, in rotate
    os.rename(source, dest)
PermissionError: [WinError 32] Le processus ne peut pas accÃ©der au fichier car ce fichier est utilisÃ© par un autre processus: "C:\\Users\\Cloud\\OneDrive\\Bureau\\UdeM\\Session d'automne\\data Science\\projet3\\python\\milestone3\\docker-project (1)\\docker-project\\serving\\flask.log" -> "C:\\Users\\Cloud\\OneDrive\\Bureau\\UdeM\\Session d'automne\\data Science\\projet3\\python\\milestone3\\docker-project (1)\\docker-project\\serving\\flask.log.1"
Call stack:
  File "C:\Users\Cloud\anaconda3\envs\ift2125\Lib\threading.py", line 1009, in _bootstrap
    self._bootstrap_inner()
  File "C:\Users\Cloud\anaconda3\envs\ift2125\Lib\threading.py", line 1052, in _bootstrap_inner
    self.run()
  File "C:\Users\Cloud\anaconda3\envs\ift2125\Lib\threading.py", line 989, in run
    self._target(*self._args, **self._kwargs)
  File "C:\Users\Cloud\anaconda3\envs\ift2125\Lib\site-packages\waitress\task.py", line 83, in handler_thread
    task.service()
  File "C:\Users\Cloud\anaconda3\envs\ift2125\Lib\site-packages\waitress\channel.py", line 430, in service
    task.service()
  File "C:\Users\Cloud\anaconda3\envs\ift2125\Lib\site-packages\waitress\task.py", line 167, in service
    self.execute()
  File "C:\Users\Cloud\anaconda3\envs\ift2125\Lib\site-packages\waitress\task.py", line 435, in execute
    app_iter = self.channel.server.application(environ, start_response)
  File "C:\Users\Cloud\anaconda3\envs\ift2125\Lib\site-packages\waitress\proxy_headers.py", line 64, in translate_proxy_headers
    return app(environ, start_response)
  File "C:\Users\Cloud\anaconda3\envs\ift2125\Lib\site-packages\flask\app.py", line 1536, in __call__
    return self.wsgi_app(environ, start_response)
  File "C:\Users\Cloud\anaconda3\envs\ift2125\Lib\site-packages\flask\app.py", line 1511, in wsgi_app
    response = self.full_dispatch_request()
  File "C:\Users\Cloud\anaconda3\envs\ift2125\Lib\site-packages\flask\app.py", line 917, in full_dispatch_request
    rv = self.dispatch_request()
  File "C:\Users\Cloud\anaconda3\envs\ift2125\Lib\site-packages\flask\app.py", line 902, in dispatch_request
    return self.ensure_sync(self.view_functions[rule.endpoint])(**view_args)  # type: ignore[no-any-return]
  File "C:\Users\Cloud\OneDrive\Bureau\UdeM\Session d'automne\data Science\projet3\python\milestone3\docker-project (1)\docker-project\serving\app.py", line 120, in download_registry_model
    app.logger.info(json)
Message: {'entity': 'thalia-cantero-udem', 'project': 'IFT6758.2024-A04', 'model': 'expected-goal-distance', 'version': 'v2'}
Arguments: ()
[2024-12-23 14:13:32,494] INFO in app: Initialisation WandB rÃ©ussie pour le projet IFT6758.2024-A04 et l'entitÃ© thalia-cantero-udem.
--- Logging error ---
Traceback (most recent call last):
  File "C:\Users\Cloud\anaconda3\envs\ift2125\Lib\logging\handlers.py", line 74, in emit
    self.doRollover()
  File "C:\Users\Cloud\anaconda3\envs\ift2125\Lib\logging\handlers.py", line 179, in doRollover
    self.rotate(self.baseFilename, dfn)
  File "C:\Users\Cloud\anaconda3\envs\ift2125\Lib\logging\handlers.py", line 115, in rotate
    os.rename(source, dest)
PermissionError: [WinError 32] Le processus ne peut pas accÃ©der au fichier car ce fichier est utilisÃ© par un autre processus: "C:\\Users\\Cloud\\OneDrive\\Bureau\\UdeM\\Session d'automne\\data Science\\projet3\\python\\milestone3\\docker-project (1)\\docker-project\\serving\\flask.log" -> "C:\\Users\\Cloud\\OneDrive\\Bureau\\UdeM\\Session d'automne\\data Science\\projet3\\python\\milestone3\\docker-project (1)\\docker-project\\serving\\flask.log.1"
Call stack:
  File "C:\Users\Cloud\anaconda3\envs\ift2125\Lib\threading.py", line 1009, in _bootstrap
    self._bootstrap_inner()
  File "C:\Users\Cloud\anaconda3\envs\ift2125\Lib\threading.py", line 1052, in _bootstrap_inner
    self.run()
  File "C:\Users\Cloud\anaconda3\envs\ift2125\Lib\threading.py", line 989, in run
    self._target(*self._args, **self._kwargs)
  File "C:\Users\Cloud\anaconda3\envs\ift2125\Lib\site-packages\waitress\task.py", line 83, in handler_thread
    task.service()
  File "C:\Users\Cloud\anaconda3\envs\ift2125\Lib\site-packages\waitress\channel.py", line 430, in service
    task.service()
  File "C:\Users\Cloud\anaconda3\envs\ift2125\Lib\site-packages\waitress\task.py", line 167, in service
    self.execute()
  File "C:\Users\Cloud\anaconda3\envs\ift2125\Lib\site-packages\waitress\task.py", line 435, in execute
    app_iter = self.channel.server.application(environ, start_response)
  File "C:\Users\Cloud\anaconda3\envs\ift2125\Lib\site-packages\waitress\proxy_headers.py", line 64, in translate_proxy_headers
    return app(environ, start_response)
  File "C:\Users\Cloud\anaconda3\envs\ift2125\Lib\site-packages\flask\app.py", line 1536, in __call__
    return self.wsgi_app(environ, start_response)
  File "C:\Users\Cloud\anaconda3\envs\ift2125\Lib\site-packages\flask\app.py", line 1511, in wsgi_app
    response = self.full_dispatch_request()
  File "C:\Users\Cloud\anaconda3\envs\ift2125\Lib\site-packages\flask\app.py", line 917, in full_dispatch_request
    rv = self.dispatch_request()
  File "C:\Users\Cloud\anaconda3\envs\ift2125\Lib\site-packages\flask\app.py", line 902, in dispatch_request
    return self.ensure_sync(self.view_functions[rule.endpoint])(**view_args)  # type: ignore[no-any-return]
  File "C:\Users\Cloud\OneDrive\Bureau\UdeM\Session d'automne\data Science\projet3\python\milestone3\docker-project (1)\docker-project\serving\app.py", line 149, in download_registry_model
    app.logger.info(f"Initialisation WandB rÃ©ussie pour le projet {project} et l'entitÃ© {entity}.")
Message: "Initialisation WandB rÃ©ussie pour le projet IFT6758.2024-A04 et l'entitÃ© thalia-cantero-udem."
Arguments: ()
[2024-12-23 14:13:32,532] INFO in app: Downloading model artifact from: thalia-cantero-udem/IFT6758.2024-A04/expected-goal-distance:v2
--- Logging error ---
Traceback (most recent call last):
  File "C:\Users\Cloud\anaconda3\envs\ift2125\Lib\logging\handlers.py", line 74, in emit
    self.doRollover()
  File "C:\Users\Cloud\anaconda3\envs\ift2125\Lib\logging\handlers.py", line 179, in doRollover
    self.rotate(self.baseFilename, dfn)
  File "C:\Users\Cloud\anaconda3\envs\ift2125\Lib\logging\handlers.py", line 115, in rotate
    os.rename(source, dest)
PermissionError: [WinError 32] Le processus ne peut pas accÃ©der au fichier car ce fichier est utilisÃ© par un autre processus: "C:\\Users\\Cloud\\OneDrive\\Bureau\\UdeM\\Session d'automne\\data Science\\projet3\\python\\milestone3\\docker-project (1)\\docker-project\\serving\\flask.log" -> "C:\\Users\\Cloud\\OneDrive\\Bureau\\UdeM\\Session d'automne\\data Science\\projet3\\python\\milestone3\\docker-project (1)\\docker-project\\serving\\flask.log.1"
Call stack:
  File "C:\Users\Cloud\anaconda3\envs\ift2125\Lib\threading.py", line 1009, in _bootstrap
    self._bootstrap_inner()
  File "C:\Users\Cloud\anaconda3\envs\ift2125\Lib\threading.py", line 1052, in _bootstrap_inner
    self.run()
  File "C:\Users\Cloud\anaconda3\envs\ift2125\Lib\threading.py", line 989, in run
    self._target(*self._args, **self._kwargs)
  File "C:\Users\Cloud\anaconda3\envs\ift2125\Lib\site-packages\waitress\task.py", line 83, in handler_thread
    task.service()
  File "C:\Users\Cloud\anaconda3\envs\ift2125\Lib\site-packages\waitress\channel.py", line 430, in service
    task.service()
  File "C:\Users\Cloud\anaconda3\envs\ift2125\Lib\site-packages\waitress\task.py", line 167, in service
    self.execute()
  File "C:\Users\Cloud\anaconda3\envs\ift2125\Lib\site-packages\waitress\task.py", line 435, in execute
    app_iter = self.channel.server.application(environ, start_response)
  File "C:\Users\Cloud\anaconda3\envs\ift2125\Lib\site-packages\waitress\proxy_headers.py", line 64, in translate_proxy_headers
    return app(environ, start_response)
  File "C:\Users\Cloud\anaconda3\envs\ift2125\Lib\site-packages\flask\app.py", line 1536, in __call__
    return self.wsgi_app(environ, start_response)
  File "C:\Users\Cloud\anaconda3\envs\ift2125\Lib\site-packages\flask\app.py", line 1511, in wsgi_app
    response = self.full_dispatch_request()
  File "C:\Users\Cloud\anaconda3\envs\ift2125\Lib\site-packages\flask\app.py", line 917, in full_dispatch_request
    rv = self.dispatch_request()
  File "C:\Users\Cloud\anaconda3\envs\ift2125\Lib\site-packages\flask\app.py", line 902, in dispatch_request
    return self.ensure_sync(self.view_functions[rule.endpoint])(**view_args)  # type: ignore[no-any-return]
  File "C:\Users\Cloud\OneDrive\Bureau\UdeM\Session d'automne\data Science\projet3\python\milestone3\docker-project (1)\docker-project\serving\app.py", line 153, in download_registry_model
    app.logger.info(f"Downloading model artifact from: {artifact_path}")
Message: 'Downloading model artifact from: thalia-cantero-udem/IFT6758.2024-A04/expected-goal-distance:v2'
Arguments: ()
[34m[1mwandb[0m:   1 of 1 files downloaded.
C:\Users\Cloud\anaconda3\envs\ift2125\Lib\site-packages\sklearn\base.py:380: InconsistentVersionWarning: Trying to unpickle estimator LogisticRegression from version 1.5.2 when using version 1.6.0. This might lead to breaking code or invalid results. Use at your own risk. For more info please refer to:
https://scikit-learn.org/stable/model_persistence.html#security-maintainability-limitations
  warnings.warn(
[2024-12-23 14:13:33,961] INFO in app: Model downloaded and loaded successfully.
--- Logging error ---
Traceback (most recent call last):
  File "C:\Users\Cloud\anaconda3\envs\ift2125\Lib\logging\handlers.py", line 74, in emit
    self.doRollover()
  File "C:\Users\Cloud\anaconda3\envs\ift2125\Lib\logging\handlers.py", line 179, in doRollover
    self.rotate(self.baseFilename, dfn)
  File "C:\Users\Cloud\anaconda3\envs\ift2125\Lib\logging\handlers.py", line 115, in rotate
    os.rename(source, dest)
PermissionError: [WinError 32] Le processus ne peut pas accÃ©der au fichier car ce fichier est utilisÃ© par un autre processus: "C:\\Users\\Cloud\\OneDrive\\Bureau\\UdeM\\Session d'automne\\data Science\\projet3\\python\\milestone3\\docker-project (1)\\docker-project\\serving\\flask.log" -> "C:\\Users\\Cloud\\OneDrive\\Bureau\\UdeM\\Session d'automne\\data Science\\projet3\\python\\milestone3\\docker-project (1)\\docker-project\\serving\\flask.log.1"
Call stack:
  File "C:\Users\Cloud\anaconda3\envs\ift2125\Lib\threading.py", line 1009, in _bootstrap
    self._bootstrap_inner()
  File "C:\Users\Cloud\anaconda3\envs\ift2125\Lib\threading.py", line 1052, in _bootstrap_inner
    self.run()
  File "C:\Users\Cloud\anaconda3\envs\ift2125\Lib\threading.py", line 989, in run
    self._target(*self._args, **self._kwargs)
  File "C:\Users\Cloud\anaconda3\envs\ift2125\Lib\site-packages\waitress\task.py", line 83, in handler_thread
    task.service()
  File "C:\Users\Cloud\anaconda3\envs\ift2125\Lib\site-packages\waitress\channel.py", line 430, in service
    task.service()
  File "C:\Users\Cloud\anaconda3\envs\ift2125\Lib\site-packages\waitress\task.py", line 167, in service
    self.execute()
  File "C:\Users\Cloud\anaconda3\envs\ift2125\Lib\site-packages\waitress\task.py", line 435, in execute
    app_iter = self.channel.server.application(environ, start_response)
  File "C:\Users\Cloud\anaconda3\envs\ift2125\Lib\site-packages\waitress\proxy_headers.py", line 64, in translate_proxy_headers
    return app(environ, start_response)
  File "C:\Users\Cloud\anaconda3\envs\ift2125\Lib\site-packages\flask\app.py", line 1536, in __call__
    return self.wsgi_app(environ, start_response)
  File "C:\Users\Cloud\anaconda3\envs\ift2125\Lib\site-packages\flask\app.py", line 1511, in wsgi_app
    response = self.full_dispatch_request()
  File "C:\Users\Cloud\anaconda3\envs\ift2125\Lib\site-packages\flask\app.py", line 917, in full_dispatch_request
    rv = self.dispatch_request()
  File "C:\Users\Cloud\anaconda3\envs\ift2125\Lib\site-packages\flask\app.py", line 902, in dispatch_request
    return self.ensure_sync(self.view_functions[rule.endpoint])(**view_args)  # type: ignore[no-any-return]
  File "C:\Users\Cloud\OneDrive\Bureau\UdeM\Session d'automne\data Science\projet3\python\milestone3\docker-project (1)\docker-project\serving\app.py", line 162, in download_registry_model
    app.logger.info("Model downloaded and loaded successfully.")
Message: 'Model downloaded and loaded successfully.'
Arguments: ()
[2024-12-23 14:14:17,381] INFO in app: {'entity': 'thalia-cantero-udem', 'project': 'IFT6758.2024-A04', 'model': 'expected-goal-model-angle-and-distance', 'version': 'v1'}
--- Logging error ---
Traceback (most recent call last):
  File "C:\Users\Cloud\anaconda3\envs\ift2125\Lib\logging\handlers.py", line 74, in emit
    self.doRollover()
  File "C:\Users\Cloud\anaconda3\envs\ift2125\Lib\logging\handlers.py", line 179, in doRollover
    self.rotate(self.baseFilename, dfn)
  File "C:\Users\Cloud\anaconda3\envs\ift2125\Lib\logging\handlers.py", line 115, in rotate
    os.rename(source, dest)
PermissionError: [WinError 32] Le processus ne peut pas accÃ©der au fichier car ce fichier est utilisÃ© par un autre processus: "C:\\Users\\Cloud\\OneDrive\\Bureau\\UdeM\\Session d'automne\\data Science\\projet3\\python\\milestone3\\docker-project (1)\\docker-project\\serving\\flask.log" -> "C:\\Users\\Cloud\\OneDrive\\Bureau\\UdeM\\Session d'automne\\data Science\\projet3\\python\\milestone3\\docker-project (1)\\docker-project\\serving\\flask.log.1"
Call stack:
  File "C:\Users\Cloud\anaconda3\envs\ift2125\Lib\threading.py", line 1009, in _bootstrap
    self._bootstrap_inner()
  File "C:\Users\Cloud\anaconda3\envs\ift2125\Lib\threading.py", line 1052, in _bootstrap_inner
    self.run()
  File "C:\Users\Cloud\anaconda3\envs\ift2125\Lib\threading.py", line 989, in run
    self._target(*self._args, **self._kwargs)
  File "C:\Users\Cloud\anaconda3\envs\ift2125\Lib\site-packages\waitress\task.py", line 83, in handler_thread
    task.service()
  File "C:\Users\Cloud\anaconda3\envs\ift2125\Lib\site-packages\waitress\channel.py", line 430, in service
    task.service()
  File "C:\Users\Cloud\anaconda3\envs\ift2125\Lib\site-packages\waitress\task.py", line 167, in service
    self.execute()
  File "C:\Users\Cloud\anaconda3\envs\ift2125\Lib\site-packages\waitress\task.py", line 435, in execute
    app_iter = self.channel.server.application(environ, start_response)
  File "C:\Users\Cloud\anaconda3\envs\ift2125\Lib\site-packages\waitress\proxy_headers.py", line 64, in translate_proxy_headers
    return app(environ, start_response)
  File "C:\Users\Cloud\anaconda3\envs\ift2125\Lib\site-packages\flask\app.py", line 1536, in __call__
    return self.wsgi_app(environ, start_response)
  File "C:\Users\Cloud\anaconda3\envs\ift2125\Lib\site-packages\flask\app.py", line 1511, in wsgi_app
    response = self.full_dispatch_request()
  File "C:\Users\Cloud\anaconda3\envs\ift2125\Lib\site-packages\flask\app.py", line 917, in full_dispatch_request
    rv = self.dispatch_request()
  File "C:\Users\Cloud\anaconda3\envs\ift2125\Lib\site-packages\flask\app.py", line 902, in dispatch_request
    return self.ensure_sync(self.view_functions[rule.endpoint])(**view_args)  # type: ignore[no-any-return]
  File "C:\Users\Cloud\OneDrive\Bureau\UdeM\Session d'automne\data Science\projet3\python\milestone3\docker-project (1)\docker-project\serving\app.py", line 120, in download_registry_model
    app.logger.info(json)
Message: {'entity': 'thalia-cantero-udem', 'project': 'IFT6758.2024-A04', 'model': 'expected-goal-model-angle-and-distance', 'version': 'v1'}
Arguments: ()
[2024-12-23 14:14:17,447] INFO in app: Initialisation WandB rÃ©ussie pour le projet IFT6758.2024-A04 et l'entitÃ© thalia-cantero-udem.
--- Logging error ---
Traceback (most recent call last):
  File "C:\Users\Cloud\anaconda3\envs\ift2125\Lib\logging\handlers.py", line 74, in emit
    self.doRollover()
  File "C:\Users\Cloud\anaconda3\envs\ift2125\Lib\logging\handlers.py", line 179, in doRollover
    self.rotate(self.baseFilename, dfn)
  File "C:\Users\Cloud\anaconda3\envs\ift2125\Lib\logging\handlers.py", line 115, in rotate
    os.rename(source, dest)
PermissionError: [WinError 32] Le processus ne peut pas accÃ©der au fichier car ce fichier est utilisÃ© par un autre processus: "C:\\Users\\Cloud\\OneDrive\\Bureau\\UdeM\\Session d'automne\\data Science\\projet3\\python\\milestone3\\docker-project (1)\\docker-project\\serving\\flask.log" -> "C:\\Users\\Cloud\\OneDrive\\Bureau\\UdeM\\Session d'automne\\data Science\\projet3\\python\\milestone3\\docker-project (1)\\docker-project\\serving\\flask.log.1"
Call stack:
  File "C:\Users\Cloud\anaconda3\envs\ift2125\Lib\threading.py", line 1009, in _bootstrap
    self._bootstrap_inner()
  File "C:\Users\Cloud\anaconda3\envs\ift2125\Lib\threading.py", line 1052, in _bootstrap_inner
    self.run()
  File "C:\Users\Cloud\anaconda3\envs\ift2125\Lib\threading.py", line 989, in run
    self._target(*self._args, **self._kwargs)
  File "C:\Users\Cloud\anaconda3\envs\ift2125\Lib\site-packages\waitress\task.py", line 83, in handler_thread
    task.service()
  File "C:\Users\Cloud\anaconda3\envs\ift2125\Lib\site-packages\waitress\channel.py", line 430, in service
    task.service()
  File "C:\Users\Cloud\anaconda3\envs\ift2125\Lib\site-packages\waitress\task.py", line 167, in service
    self.execute()
  File "C:\Users\Cloud\anaconda3\envs\ift2125\Lib\site-packages\waitress\task.py", line 435, in execute
    app_iter = self.channel.server.application(environ, start_response)
  File "C:\Users\Cloud\anaconda3\envs\ift2125\Lib\site-packages\waitress\proxy_headers.py", line 64, in translate_proxy_headers
    return app(environ, start_response)
  File "C:\Users\Cloud\anaconda3\envs\ift2125\Lib\site-packages\flask\app.py", line 1536, in __call__
    return self.wsgi_app(environ, start_response)
  File "C:\Users\Cloud\anaconda3\envs\ift2125\Lib\site-packages\flask\app.py", line 1511, in wsgi_app
    response = self.full_dispatch_request()
  File "C:\Users\Cloud\anaconda3\envs\ift2125\Lib\site-packages\flask\app.py", line 917, in full_dispatch_request
    rv = self.dispatch_request()
  File "C:\Users\Cloud\anaconda3\envs\ift2125\Lib\site-packages\flask\app.py", line 902, in dispatch_request
    return self.ensure_sync(self.view_functions[rule.endpoint])(**view_args)  # type: ignore[no-any-return]
  File "C:\Users\Cloud\OneDrive\Bureau\UdeM\Session d'automne\data Science\projet3\python\milestone3\docker-project (1)\docker-project\serving\app.py", line 149, in download_registry_model
    app.logger.info(f"Initialisation WandB rÃ©ussie pour le projet {project} et l'entitÃ© {entity}.")
Message: "Initialisation WandB rÃ©ussie pour le projet IFT6758.2024-A04 et l'entitÃ© thalia-cantero-udem."
Arguments: ()
[2024-12-23 14:14:17,500] INFO in app: Downloading model artifact from: thalia-cantero-udem/IFT6758.2024-A04/expected-goal-model-angle-and-distance:v1
--- Logging error ---
Traceback (most recent call last):
  File "C:\Users\Cloud\anaconda3\envs\ift2125\Lib\logging\handlers.py", line 74, in emit
    self.doRollover()
  File "C:\Users\Cloud\anaconda3\envs\ift2125\Lib\logging\handlers.py", line 179, in doRollover
    self.rotate(self.baseFilename, dfn)
  File "C:\Users\Cloud\anaconda3\envs\ift2125\Lib\logging\handlers.py", line 115, in rotate
    os.rename(source, dest)
PermissionError: [WinError 32] Le processus ne peut pas accÃ©der au fichier car ce fichier est utilisÃ© par un autre processus: "C:\\Users\\Cloud\\OneDrive\\Bureau\\UdeM\\Session d'automne\\data Science\\projet3\\python\\milestone3\\docker-project (1)\\docker-project\\serving\\flask.log" -> "C:\\Users\\Cloud\\OneDrive\\Bureau\\UdeM\\Session d'automne\\data Science\\projet3\\python\\milestone3\\docker-project (1)\\docker-project\\serving\\flask.log.1"
Call stack:
  File "C:\Users\Cloud\anaconda3\envs\ift2125\Lib\threading.py", line 1009, in _bootstrap
    self._bootstrap_inner()
  File "C:\Users\Cloud\anaconda3\envs\ift2125\Lib\threading.py", line 1052, in _bootstrap_inner
    self.run()
  File "C:\Users\Cloud\anaconda3\envs\ift2125\Lib\threading.py", line 989, in run
    self._target(*self._args, **self._kwargs)
  File "C:\Users\Cloud\anaconda3\envs\ift2125\Lib\site-packages\waitress\task.py", line 83, in handler_thread
    task.service()
  File "C:\Users\Cloud\anaconda3\envs\ift2125\Lib\site-packages\waitress\channel.py", line 430, in service
    task.service()
  File "C:\Users\Cloud\anaconda3\envs\ift2125\Lib\site-packages\waitress\task.py", line 167, in service
    self.execute()
  File "C:\Users\Cloud\anaconda3\envs\ift2125\Lib\site-packages\waitress\task.py", line 435, in execute
    app_iter = self.channel.server.application(environ, start_response)
  File "C:\Users\Cloud\anaconda3\envs\ift2125\Lib\site-packages\waitress\proxy_headers.py", line 64, in translate_proxy_headers
    return app(environ, start_response)
  File "C:\Users\Cloud\anaconda3\envs\ift2125\Lib\site-packages\flask\app.py", line 1536, in __call__
    return self.wsgi_app(environ, start_response)
  File "C:\Users\Cloud\anaconda3\envs\ift2125\Lib\site-packages\flask\app.py", line 1511, in wsgi_app
    response = self.full_dispatch_request()
  File "C:\Users\Cloud\anaconda3\envs\ift2125\Lib\site-packages\flask\app.py", line 917, in full_dispatch_request
    rv = self.dispatch_request()
  File "C:\Users\Cloud\anaconda3\envs\ift2125\Lib\site-packages\flask\app.py", line 902, in dispatch_request
    return self.ensure_sync(self.view_functions[rule.endpoint])(**view_args)  # type: ignore[no-any-return]
  File "C:\Users\Cloud\OneDrive\Bureau\UdeM\Session d'automne\data Science\projet3\python\milestone3\docker-project (1)\docker-project\serving\app.py", line 153, in download_registry_model
    app.logger.info(f"Downloading model artifact from: {artifact_path}")
Message: 'Downloading model artifact from: thalia-cantero-udem/IFT6758.2024-A04/expected-goal-model-angle-and-distance:v1'
Arguments: ()
[34m[1mwandb[0m:   1 of 1 files downloaded.
[2024-12-23 14:14:18,316] ERROR in app: Failed to download model: [Errno 2] No such file or directory: "C:\\Users\\Cloud\\OneDrive\\Bureau\\UdeM\\Session d'automne\\data Science\\projet3\\python\\milestone3\\docker-project (1)\\docker-project\\models\\expected-goal-model-angle-and-distance.pkl"
--- Logging error ---
Traceback (most recent call last):
  File "C:\Users\Cloud\OneDrive\Bureau\UdeM\Session d'automne\data Science\projet3\python\milestone3\docker-project (1)\docker-project\serving\app.py", line 160, in download_registry_model
    loaded_model = joblib.load(model_file_path)
                   ^^^^^^^^^^^^^^^^^^^^^^^^^^^^
  File "C:\Users\Cloud\anaconda3\envs\ift2125\Lib\site-packages\joblib\numpy_pickle.py", line 650, in load
    with open(filename, 'rb') as f:
         ^^^^^^^^^^^^^^^^^^^^
FileNotFoundError: [Errno 2] No such file or directory: "C:\\Users\\Cloud\\OneDrive\\Bureau\\UdeM\\Session d'automne\\data Science\\projet3\\python\\milestone3\\docker-project (1)\\docker-project\\models\\expected-goal-model-angle-and-distance.pkl"

During handling of the above exception, another exception occurred:

Traceback (most recent call last):
  File "C:\Users\Cloud\anaconda3\envs\ift2125\Lib\logging\handlers.py", line 74, in emit
    self.doRollover()
  File "C:\Users\Cloud\anaconda3\envs\ift2125\Lib\logging\handlers.py", line 179, in doRollover
    self.rotate(self.baseFilename, dfn)
  File "C:\Users\Cloud\anaconda3\envs\ift2125\Lib\logging\handlers.py", line 115, in rotate
    os.rename(source, dest)
PermissionError: [WinError 32] Le processus ne peut pas accÃ©der au fichier car ce fichier est utilisÃ© par un autre processus: "C:\\Users\\Cloud\\OneDrive\\Bureau\\UdeM\\Session d'automne\\data Science\\projet3\\python\\milestone3\\docker-project (1)\\docker-project\\serving\\flask.log" -> "C:\\Users\\Cloud\\OneDrive\\Bureau\\UdeM\\Session d'automne\\data Science\\projet3\\python\\milestone3\\docker-project (1)\\docker-project\\serving\\flask.log.1"
Call stack:
  File "C:\Users\Cloud\anaconda3\envs\ift2125\Lib\threading.py", line 1009, in _bootstrap
    self._bootstrap_inner()
  File "C:\Users\Cloud\anaconda3\envs\ift2125\Lib\threading.py", line 1052, in _bootstrap_inner
    self.run()
  File "C:\Users\Cloud\anaconda3\envs\ift2125\Lib\threading.py", line 989, in run
    self._target(*self._args, **self._kwargs)
  File "C:\Users\Cloud\anaconda3\envs\ift2125\Lib\site-packages\waitress\task.py", line 83, in handler_thread
    task.service()
  File "C:\Users\Cloud\anaconda3\envs\ift2125\Lib\site-packages\waitress\channel.py", line 430, in service
    task.service()
  File "C:\Users\Cloud\anaconda3\envs\ift2125\Lib\site-packages\waitress\task.py", line 167, in service
    self.execute()
  File "C:\Users\Cloud\anaconda3\envs\ift2125\Lib\site-packages\waitress\task.py", line 435, in execute
    app_iter = self.channel.server.application(environ, start_response)
  File "C:\Users\Cloud\anaconda3\envs\ift2125\Lib\site-packages\waitress\proxy_headers.py", line 64, in translate_proxy_headers
    return app(environ, start_response)
  File "C:\Users\Cloud\anaconda3\envs\ift2125\Lib\site-packages\flask\app.py", line 1536, in __call__
    return self.wsgi_app(environ, start_response)
  File "C:\Users\Cloud\anaconda3\envs\ift2125\Lib\site-packages\flask\app.py", line 1511, in wsgi_app
    response = self.full_dispatch_request()
  File "C:\Users\Cloud\anaconda3\envs\ift2125\Lib\site-packages\flask\app.py", line 917, in full_dispatch_request
    rv = self.dispatch_request()
  File "C:\Users\Cloud\anaconda3\envs\ift2125\Lib\site-packages\flask\app.py", line 902, in dispatch_request
    return self.ensure_sync(self.view_functions[rule.endpoint])(**view_args)  # type: ignore[no-any-return]
  File "C:\Users\Cloud\OneDrive\Bureau\UdeM\Session d'automne\data Science\projet3\python\milestone3\docker-project (1)\docker-project\serving\app.py", line 165, in download_registry_model
    app.logger.error(f"Failed to download model: {e}")
Message: 'Failed to download model: [Errno 2] No such file or directory: "C:\\\\Users\\\\Cloud\\\\OneDrive\\\\Bureau\\\\UdeM\\\\Session d\'automne\\\\data Science\\\\projet3\\\\python\\\\milestone3\\\\docker-project (1)\\\\docker-project\\\\models\\\\expected-goal-model-angle-and-distance.pkl"'
Arguments: ()
